8=FIX.4.49=261635=X49=CNX34=352=20160701-02:31:12.99056=gkgoh1003fixstr262=10697z0uv039268=41279=0269=0278=319555=USD/JPY270=102.913271=1000000346=1279=0269=0278=316955=USD/JPY270=102.912271=1500000346=2279=0269=0278=317355=USD/JPY270=102.911271=3000000346=2279=0269=0278=318155=USD/JPY270=102.91271=500000346=1279=0269=0278=318355=USD/JPY270=102.909271=2500000346=3279=0269=0278=317755=USD/JPY270=102.908271=2000000346=3279=0269=0278=318955=USD/JPY270=102.907271=6000000346=3279=0269=0278=318555=USD/JPY270=102.906271=1000000346=1279=0269=0278=317155=USD/JPY270=102.905271=2000000346=2279=0269=0278=317955=USD/JPY270=102.904271=2000000346=3279=0269=0278=311955=USD/JPY270=102.903271=500000346=1279=0269=0278=319155=USD/JPY270=102.901271=3500000346=3279=0269=0278=313155=USD/JPY270=102.90271=1000000346=1279=0269=0278=317555=USD/JPY270=102.896271=2000000346=3279=0269=0278=316755=USD/JPY270=102.895271=2000000346=2279=0269=0278=306155=USD/JPY270=102.893271=500000346=1279=0269=0278=316555=USD/JPY270=102.892271=1000000346=1279=0269=0278=316155=USD/JPY270=102.89271=2000000346=1279=0269=0278=315155=USD/JPY270=102.888271=4900000346=2279=0269=0278=315755=USD/JPY270=102.886271=5000000346=1279=0269=0278=314755=USD/JPY270=102.883271=3000000346=1279=0269=1278=320255=USD/JPY270=102.921271=500000346=1279=0269=1278=311655=USD/JPY270=102.922271=1500000346=2279=0269=1278=320655=USD/JPY270=102.923271=3000000346=4279=0269=1278=321055=USD/JPY270=102.925271=4500000346=5279=0269=1278=321255=USD/JPY270=102.926271=6500000346=4279=0269=1278=322855=USD/JPY270=102.927271=2000000346=2279=0269=1278=310055=USD/JPY270=102.928271=4500000346=4279=0269=1278=321455=USD/JPY270=102.929271=500000346=1279=0269=1278=309455=USD/JPY270=102.93271=1500000346=2279=0269=1278=310455=USD/JPY270=102.931271=500000346=1279=0269=1278=322055=USD/JPY270=102.932271=1000000346=1279=0269=1278=321655=USD/JPY270=102.936271=1000000346=1279=0269=1278=323055=USD/JPY270=102.937271=500000346=1279=0269=1278=323455=USD/JPY270=102.938271=1000000346=1279=0269=1278=322255=USD/JPY270=102.941271=1000000346=1279=0269=1278=325255=USD/JPY270=102.942271=500000346=1279=0269=1278=324255=USD/JPY270=102.945271=3500000346=2279=0269=1278=323655=USD/JPY270=102.946271=1000000346=1279=0269=1278=323255=USD/JPY270=102.947271=11000000346=3279=0269=1278=309655=USD/JPY270=102.949271=1000000346=110=217
8=FIX.4.49=17835=X49=CNX34=452=20160701-02:31:13.24256=gkgoh1003fixstr262=10697z0uv039268=2279=0269=1278=311655=USD/JPY270=102.922271=2000000346=3279=2269=1278=320255=USD/JPY10=018
8=FIX.4.49=95535=X49=CNX34=552=20160701-02:31:13.24356=gkgoh1003fixstr262=10697z0uv039268=16279=0269=0278=317955=USD/JPY270=102.904271=6000000346=4279=0269=0278=315155=USD/JPY270=102.888271=900000346=1279=0269=0278=318155=USD/JPY270=102.91271=1500000346=2279=2269=0278=317555=USD/JPY279=0269=0278=317755=USD/JPY270=102.908271=4000000346=4279=2269=0278=316155=USD/JPY279=0269=0278=317355=USD/JPY270=102.911271=4000000346=4279=0269=1278=310455=USD/JPY270=102.931271=1500000346=2279=2269=1278=309655=USD/JPY279=0269=1278=321455=USD/JPY270=102.929271=4500000346=2279=0269=1278=323255=USD/JPY270=102.947271=5000000346=1279=0269=1278=322855=USD/JPY270=102.927271=4000000346=3279=0269=1278=321055=USD/JPY270=102.925271=5000000346=6279=0269=1278=324255=USD/JPY270=102.945271=3000000346=1279=0269=1278=311655=USD/JPY270=102.922271=2500000346=4279=2269=1278=325255=USD/JPY10=008
8=FIX.4.49=33235=X49=CNX34=652=20160701-02:31:13.24356=gkgoh1003fixstr262=10697z0uv039268=4279=0269=0278=317755=USD/JPY270=102.908271=8000000346=5279=0269=0278=318955=USD/JPY270=102.907271=2000000346=2279=0269=1278=322855=USD/JPY270=102.927271=8000000346=4279=0269=1278=321255=USD/JPY270=102.926271=2500000346=310=139
8=FIX.4.49=70835=X49=CNX34=752=20160701-02:31:13.24456=gkgoh1003fixstr262=10697z0uv039268=12279=0269=0278=317555=USD/JPY270=102.896271=1000000346=1279=0269=0278=316755=USD/JPY270=102.895271=1000000346=1279=0269=0278=316955=USD/JPY270=102.912271=2500000346=3279=2269=0278=319555=USD/JPY279=0269=0278=318955=USD/JPY270=102.907271=2500000346=3279=0269=0278=317755=USD/JPY270=102.908271=7500000346=4279=0269=0278=315355=USD/JPY270=102.887271=900000346=1279=2269=0278=315155=USD/JPY279=0269=1278=323055=USD/JPY270=102.937271=1500000346=2279=2269=1278=321655=USD/JPY279=0269=1278=324255=USD/JPY270=102.945271=4000000346=2279=2269=1278=323655=USD/JPY10=134
8=FIX.4.49=45535=X49=CNX34=852=20160701-02:31:13.24556=gkgoh1003fixstr262=10697z0uv039268=6279=0269=0278=318755=USD/JPY270=102.902271=1000000346=1279=0269=0278=319155=USD/JPY270=102.901271=2500000346=3279=0269=1278=320455=USD/JPY270=102.924271=500000346=1279=0269=1278=320655=USD/JPY270=102.923271=2500000346=3279=0269=1278=322855=USD/JPY270=102.927271=7000000346=3279=0269=1278=310055=USD/JPY270=102.928271=5500000346=410=049
8=FIX.4.49=33135=X49=CNX34=952=20160701-02:31:13.74156=gkgoh1003fixstr262=10697z0uv039268=4279=0269=0278=318155=USD/JPY270=102.91271=2000000346=3279=0269=0278=318355=USD/JPY270=102.909271=2000000346=2279=0269=1278=320655=USD/JPY270=102.923271=3000000346=4279=0269=1278=311655=USD/JPY270=102.922271=2000000346=310=053
8=FIX.4.49=27335=X49=CNX34=1052=20160701-02:31:13.74156=gkgoh1003fixstr262=10697z0uv039268=4279=0269=0278=316355=USD/JPY270=102.885271=5000000346=1279=2269=0278=315755=USD/JPY279=0269=1278=323655=USD/JPY270=102.946271=5000000346=1279=2269=1278=323255=USD/JPY10=203
8=FIX.4.49=20935=X49=CNX34=1152=20160701-02:31:13.74156=gkgoh1003fixstr262=10697z0uv039268=2279=0269=0278=318755=USD/JPY270=102.902271=2000000346=2279=0269=0278=319155=USD/JPY270=102.901271=1500000346=210=180
8=FIX.4.49=46035=X49=CNX34=1252=20160701-02:31:13.74256=gkgoh1003fixstr262=10697z0uv039268=8279=0269=0278=312755=USD/JPY270=102.891271=1000000346=1279=2269=0278=316555=USD/JPY279=0269=0278=315555=USD/JPY270=102.894271=1000000346=1279=2269=0278=316755=USD/JPY279=0269=1278=322655=USD/JPY270=102.94271=1000000346=1279=2269=1278=322255=USD/JPY279=0269=1278=323055=USD/JPY270=102.937271=2500000346=3279=2269=1278=323455=USD/JPY10=127
8=FIX.4.49=17935=X49=CNX34=1352=20160701-02:31:13.74256=gkgoh1003fixstr262=10697z0uv039268=2279=0269=0278=318755=USD/JPY270=102.902271=1000000346=1279=2269=1278=320455=USD/JPY10=076
8=FIX.4.49=24135=X49=CNX34=1452=20160701-02:31:13.74256=gkgoh1003fixstr262=10697z0uv039268=3279=0269=0278=316355=USD/JPY270=102.885271=8000000346=2279=2269=0278=314755=USD/JPY279=0269=1278=320655=USD/JPY270=102.923271=3500000346=510=075
8=FIX.4.49=14735=X49=CNX34=1552=20160701-02:31:13.74356=gkgoh1003fixstr262=10697z0uv039268=1279=0269=0278=319155=USD/JPY270=102.901271=2500000346=210=202
8=FIX.4.49=55035=X49=CNX34=1652=20160701-02:31:15.24256=gkgoh1003fixstr262=10697z0uv039268=8279=0269=0278=315755=USD/JPY270=102.886271=5000000346=1279=0269=0278=316355=USD/JPY270=102.885271=3000000346=1279=0269=1278=321055=USD/JPY270=102.925271=6000000346=7279=0269=1278=321255=USD/JPY270=102.926271=1500000346=2279=0269=1278=309455=USD/JPY270=102.93271=2000000346=3279=0269=1278=310455=USD/JPY270=102.931271=1000000346=1279=0269=1278=323255=USD/JPY270=102.947271=5000000346=1279=2269=1278=323655=USD/JPY10=209
8=FIX.4.49=64735=X49=CNX34=1752=20160701-02:31:15.24356=gkgoh1003fixstr262=10697z0uv039268=11279=0269=0278=319155=USD/JPY270=102.901271=3500000346=3279=2269=0278=318755=USD/JPY279=0269=0278=316555=USD/JPY270=102.892271=1000000346=1279=2269=0278=312755=USD/JPY279=0269=0278=316755=USD/JPY270=102.895271=1000000346=1279=2269=0278=315555=USD/JPY279=0269=1278=320455=USD/JPY270=102.924271=500000346=1279=0269=1278=322255=USD/JPY270=102.941271=1000000346=1279=2269=1278=322655=USD/JPY279=0269=1278=323455=USD/JPY270=102.938271=1000000346=1279=0269=1278=323055=USD/JPY270=102.937271=1500000346=210=140
8=FIX.4.49=39435=X49=CNX34=1852=20160701-02:31:15.24356=gkgoh1003fixstr262=10697z0uv039268=5279=0269=0278=311955=USD/JPY270=102.903271=1500000346=2279=0269=0278=317955=USD/JPY270=102.904271=5000000346=3279=0269=1278=320655=USD/JPY270=102.923271=3000000346=4279=0269=1278=322055=USD/JPY270=102.932271=2000000346=2279=0269=1278=309455=USD/JPY270=102.93271=1000000346=210=099
8=FIX.4.49=33235=X49=CNX34=1952=20160701-02:31:15.74256=gkgoh1003fixstr262=10697z0uv039268=4279=0269=0278=318355=USD/JPY270=102.909271=2500000346=3279=0269=0278=318155=USD/JPY270=102.91271=1500000346=2279=0269=1278=311655=USD/JPY270=102.922271=2500000346=4279=0269=1278=320655=USD/JPY270=102.923271=2500000346=310=124
8=FIX.4.49=33235=X49=CNX34=2052=20160701-02:31:15.74356=gkgoh1003fixstr262=10697z0uv039268=4279=0269=0278=318755=USD/JPY270=102.902271=500000346=1279=0269=0278=317955=USD/JPY270=102.904271=4500000346=2279=0269=1278=322855=USD/JPY270=102.927271=7500000346=4279=0269=1278=321255=USD/JPY270=102.926271=1000000346=110=129
8=FIX.4.49=48835=X49=CNX34=2152=20160701-02:31:15.74356=gkgoh1003fixstr262=10697z0uv039268=8279=0269=0278=316155=USD/JPY270=102.89271=500000346=1279=2269=0278=306155=USD/JPY279=0269=0278=316355=USD/JPY270=102.885271=8000000346=2279=2269=0278=315755=USD/JPY279=0269=1278=325255=USD/JPY270=102.942271=500000346=1279=0269=1278=323055=USD/JPY270=102.937271=1000000346=1279=0269=1278=323655=USD/JPY270=102.946271=5000000346=1279=2269=1278=323255=USD/JPY10=160
8=FIX.4.49=55535=X49=CNX34=2252=20160701-02:31:15.74456=gkgoh1003fixstr262=10697z0uv039268=10279=0269=0278=312755=USD/JPY270=102.891271=1000000346=1279=2269=0278=316555=USD/JPY279=0269=0278=315555=USD/JPY270=102.894271=1000000346=1279=2269=0278=316755=USD/JPY279=0269=1278=322655=USD/JPY270=102.94271=1000000346=1279=2269=1278=322255=USD/JPY279=0269=1278=323055=USD/JPY270=102.937271=2000000346=2279=2269=1278=323455=USD/JPY279=2269=1278=320455=USD/JPY279=0269=1278=320655=USD/JPY270=102.923271=3000000346=410=028
8=FIX.4.49=20835=X49=CNX34=2352=20160701-02:31:16.24556=gkgoh1003fixstr262=10697z0uv039268=2279=0269=0278=317355=USD/JPY270=102.911271=4500000346=5279=0269=0278=318155=USD/JPY270=102.91271=1000000346=110=134
8=FIX.4.49=33335=X49=CNX34=2452=20160701-02:31:16.24556=gkgoh1003fixstr262=10697z0uv039268=4279=0269=0278=318355=USD/JPY270=102.909271=3500000346=4279=0269=0278=317755=USD/JPY270=102.908271=6500000346=3279=0269=1278=311655=USD/JPY270=102.922271=3500000346=5279=0269=1278=320655=USD/JPY270=102.923271=2000000346=310=185
8=FIX.4.49=73835=X49=CNX34=2552=20160701-02:31:16.24556=gkgoh1003fixstr262=10697z0uv039268=11279=0269=0278=317955=USD/JPY270=102.904271=5500000346=3279=0269=0278=317155=USD/JPY270=102.905271=1000000346=1279=0269=0278=316755=USD/JPY270=102.895271=1000000346=1279=2269=0278=317555=USD/JPY279=0269=1278=322855=USD/JPY270=102.927271=7500000346=4279=0269=1278=321055=USD/JPY270=102.925271=5000000346=6279=0269=1278=310855=USD/JPY270=102.933271=1000000346=1279=0269=1278=322055=USD/JPY270=102.932271=1000000346=1279=0269=1278=321455=USD/JPY270=102.929271=5500000346=3279=0269=1278=323455=USD/JPY270=102.938271=1000000346=1279=0269=1278=323055=USD/JPY270=102.937271=1000000346=110=024
8=FIX.4.49=30335=X49=CNX34=2652=20160701-02:31:16.24556=gkgoh1003fixstr262=10697z0uv039268=4279=0269=0278=315755=USD/JPY270=102.886271=5000000346=1279=0269=0278=316355=USD/JPY270=102.885271=3000000346=1279=0269=1278=323255=USD/JPY270=102.947271=5000000346=1279=2269=1278=323655=USD/JPY10=066
8=FIX.4.49=49035=X49=CNX34=2752=20160701-02:31:16.24656=gkgoh1003fixstr262=10697z0uv039268=8279=0269=0278=315155=USD/JPY270=102.888271=900000346=1279=2269=0278=315355=USD/JPY279=0269=0278=316555=USD/JPY270=102.892271=1000000346=1279=2269=0278=312755=USD/JPY279=0269=1278=323655=USD/JPY270=102.946271=1000000346=1279=0269=1278=324255=USD/JPY270=102.945271=3000000346=1279=0269=1278=322255=USD/JPY270=102.941271=1000000346=1279=2269=1278=322655=USD/JPY10=250
8=FIX.4.49=17935=X49=CNX34=2852=20160701-02:31:16.24656=gkgoh1003fixstr262=10697z0uv039268=2279=0269=0278=316755=USD/JPY270=102.895271=2000000346=2279=2269=0278=315555=USD/JPY10=099
8=FIX.4.49=17935=X49=CNX34=2952=20160701-02:31:16.24656=gkgoh1003fixstr262=10697z0uv039268=2279=0269=1278=323455=USD/JPY270=102.938271=2000000346=2279=2269=1278=323055=USD/JPY10=089
8=FIX.4.49=73735=X49=CNX34=3052=20160701-02:31:16.74856=gkgoh1003fixstr262=10697z0uv039268=11279=0269=0278=318155=USD/JPY270=102.91271=2000000346=2279=2269=0278=317155=USD/JPY279=0269=0278=317355=USD/JPY270=102.911271=5500000346=6279=0269=0278=318355=USD/JPY270=102.909271=2000000346=2279=0269=0278=316955=USD/JPY270=102.912271=3000000346=4279=0269=1278=322855=USD/JPY270=102.927271=8500000346=5279=0269=1278=310055=USD/JPY270=102.928271=4500000346=3279=0269=1278=321255=USD/JPY270=102.926271=2000000346=2279=0269=1278=320655=USD/JPY270=102.923271=1000000346=2279=0269=1278=321055=USD/JPY270=102.925271=5500000346=7279=0269=1278=311655=USD/JPY270=102.922271=3000000346=410=231
8=FIX.4.49=33235=X49=CNX34=3152=20160701-02:31:16.74956=gkgoh1003fixstr262=10697z0uv039268=4279=0269=0278=317355=USD/JPY270=102.911271=6000000346=7279=0269=0278=317755=USD/JPY270=102.908271=6000000346=2279=0269=1278=321255=USD/JPY270=102.926271=2500000346=3279=0269=1278=320655=USD/JPY270=102.923271=500000346=110=129
8=FIX.4.49=82735=X49=CNX34=3252=20160701-02:31:16.75056=gkgoh1003fixstr262=10697z0uv039268=12279=0269=0278=319555=USD/JPY270=102.913271=500000346=1279=0269=0278=317355=USD/JPY270=102.911271=5500000346=6279=0269=0278=318555=USD/JPY270=102.906271=1500000346=2279=0269=0278=317955=USD/JPY270=102.904271=5000000346=2279=0269=0278=317155=USD/JPY270=102.905271=500000346=1279=0269=0278=311955=USD/JPY270=102.903271=1000000346=1279=0269=1278=321055=USD/JPY270=102.925271=6000000346=8279=0269=1278=311655=USD/JPY270=102.922271=2500000346=3279=0269=1278=309455=USD/JPY270=102.93271=1500000346=3279=0269=1278=310055=USD/JPY270=102.928271=4000000346=2279=0269=1278=310455=USD/JPY270=102.931271=1500000346=2279=0269=1278=321455=USD/JPY270=102.929271=5000000346=210=223
8=FIX.4.49=58035=X49=CNX34=3352=20160701-02:31:16.75056=gkgoh1003fixstr262=10697z0uv039268=8279=0269=0278=307755=USD/JPY270=102.914271=500000346=1279=0269=0278=316955=USD/JPY270=102.912271=2500000346=3279=0269=0278=319555=USD/JPY270=102.913271=2500000346=2279=0269=0278=317355=USD/JPY270=102.911271=3500000346=5279=0269=1278=321255=USD/JPY270=102.926271=3000000346=4279=0269=1278=321055=USD/JPY270=102.925271=5500000346=7279=0269=1278=321455=USD/JPY270=102.929271=7000000346=3279=0269=1278=310055=USD/JPY270=102.928271=2000000346=110=084
8=FIX.4.49=77035=X49=CNX34=3452=20160701-02:31:16.75256=gkgoh1003fixstr262=10697z0uv039268=12279=0269=0278=317355=USD/JPY270=102.911271=4500000346=6279=0269=0278=318355=USD/JPY270=102.909271=1000000346=1279=0269=0278=318755=USD/JPY270=102.902271=1500000346=2279=2269=0278=313155=USD/JPY279=0269=0278=318555=USD/JPY270=102.906271=2500000346=3279=0269=0278=317955=USD/JPY270=102.904271=4000000346=1279=0269=1278=320455=USD/JPY270=102.924271=1000000346=1279=0269=1278=311655=USD/JPY270=102.922271=1500000346=2279=0269=1278=311455=USD/JPY270=102.935271=1000000346=1279=2269=1278=310855=USD/JPY279=0269=1278=310455=USD/JPY270=102.931271=2500000346=3279=0269=1278=321455=USD/JPY270=102.929271=6000000346=210=138
8=FIX.4.49=76735=X49=CNX34=3552=20160701-02:31:16.75256=gkgoh1003fixstr262=10697z0uv039268=11279=0269=0278=312955=USD/JPY270=102.897271=1000000346=1279=0269=0278=316755=USD/JPY270=102.895271=1000000346=1279=0269=0278=318955=USD/JPY270=102.907271=1000000346=2279=0269=0278=318755=USD/JPY270=102.902271=1000000346=1279=0269=0278=317755=USD/JPY270=102.908271=7000000346=3279=0269=0278=318355=USD/JPY270=102.909271=2000000346=2279=0269=1278=322655=USD/JPY270=102.94271=1000000346=1279=0269=1278=323455=USD/JPY270=102.938271=1000000346=1279=0269=1278=310055=USD/JPY270=102.928271=3500000346=3279=0269=1278=322855=USD/JPY270=102.927271=8000000346=4279=0269=1278=321055=USD/JPY270=102.925271=4500000346=610=112
8=FIX.4.49=20935=X49=CNX34=3652=20160701-02:31:16.75356=gkgoh1003fixstr262=10697z0uv039268=2279=0269=0278=319555=USD/JPY270=102.913271=3500000346=3279=0269=0278=317355=USD/JPY270=102.911271=3500000346=510=207
8=FIX.4.49=39635=X49=CNX34=3752=20160701-02:31:16.75356=gkgoh1003fixstr262=10697z0uv039268=6279=0269=0278=316555=USD/JPY270=102.892271=6000000346=2279=2269=0278=315755=USD/JPY279=0269=1278=320655=USD/JPY270=102.923271=1500000346=2279=0269=1278=311655=USD/JPY270=102.922271=500000346=1279=0269=1278=323855=USD/JPY270=102.944271=5000000346=1279=2269=1278=323255=USD/JPY10=147
8=FIX.4.49=45735=X49=CNX34=3852=20160701-02:31:16.75456=gkgoh1003fixstr262=10697z0uv039268=6279=0269=0278=318155=USD/JPY270=102.91271=6000000346=3279=0269=0278=317755=USD/JPY270=102.908271=3000000346=2279=0269=1278=321255=USD/JPY270=102.926271=4000000346=5279=0269=1278=321055=USD/JPY270=102.925271=3500000346=5279=0269=1278=321455=USD/JPY270=102.929271=10000000346=3279=0269=1278=322855=USD/JPY270=102.927271=4000000346=310=162
8=FIX.4.49=33335=X49=CNX34=3952=20160701-02:31:16.75456=gkgoh1003fixstr262=10697z0uv039268=4279=0269=0278=307755=USD/JPY270=102.914271=1500000346=2279=0269=0278=316955=USD/JPY270=102.912271=1500000346=2279=0269=1278=322855=USD/JPY270=102.927271=5000000346=4279=0269=1278=321255=USD/JPY270=102.926271=3000000346=410=187
8=FIX.4.49=27235=X49=CNX34=4052=20160701-02:31:16.75556=gkgoh1003fixstr262=10697z0uv039268=4279=0269=0278=306155=USD/JPY270=102.893271=900000346=1279=2269=0278=315155=USD/JPY279=0269=1278=324055=USD/JPY270=102.943271=1000000346=1279=2269=1278=323655=USD/JPY10=151
8=FIX.4.49=49035=X49=CNX34=4152=20160701-02:31:16.75556=gkgoh1003fixstr262=10697z0uv039268=8279=0269=0278=312955=USD/JPY270=102.897271=2000000346=2279=0269=0278=316555=USD/JPY270=102.892271=5000000346=1279=0269=0278=313155=USD/JPY270=102.90271=1000000346=1279=2269=0278=316755=USD/JPY279=0269=1278=322455=USD/JPY270=102.939271=1000000346=1279=2269=1278=322255=USD/JPY279=0269=1278=323055=USD/JPY270=102.937271=1000000346=1279=2269=1278=323455=USD/JPY10=243
8=FIX.4.49=20935=X49=CNX34=4252=20160701-02:31:16.75656=gkgoh1003fixstr262=10697z0uv039268=2279=0269=0278=318755=USD/JPY270=102.902271=2000000346=2279=0269=1278=321055=USD/JPY270=102.925271=4000000346=610=194
